<robot name="test_robot">
    <link name="base_link">
        <visual>
            <geometry>
                <box size="0.16 0.16 0.12"/>
            </geometry>
            <origin rpy="0 0 0" xyz="0 0 0.085"/>
            <material name="white">
                <color rgba="1 1 1 1"/>
            </material>
        </visual>
        <collision>
            <geometry>
                <box size="0.16 0.16 0.12"/>
            </geometry>
            <origin rpy="0 0 0" xyz="0 0 0.085"/>
        </collision>
        <inertial>
            <mass value="10"/>
            <inertia ixx="0.4" ixy="0.0" ixz="0.0" iyy="0.4" iyz="0.0" izz="0.2"/>
        </inertial>
    </link>
  
    <link name="lwheel">
        <visual>
            <geometry>
                <cylinder length="0.008" radius="0.046"/>
            </geometry>
            <origin rpy="0 0 0" xyz="0 0 0"/>
            <material name="black">
                <color rgba="0 0 0 1"/>
            </material>
        </visual>
        <collision>
            <geometry>
                <cylinder length="0.008" radius="0.046"/>
            </geometry>
            <origin rpy="0 0 0" xyz="0 0 0"/>
        </collision>
        <inertial>
            <mass value="5"/>
            <inertia ixx="0.2" ixy="0.0" ixz="0.0" iyy="0.2" iyz="0.0" izz="0.1"/>
        </inertial>
    </link>
  
    <joint name="base_to_lwheel" type="continuous">
        <parent link="base_link"/>
        <child link="lwheel"/>
        <origin xyz="0 0.115 0.046" rpy="1.5708 0 0"/>
    </joint>
  
    <link name="rwheel">
        <visual>
            <geometry>
                <cylinder length="0.008" radius="0.046"/>
            </geometry>
            <origin rpy="0 0 0" xyz="0 0 0"/>
            <material name="black">
                <color rgba="0 0 0 1"/>
            </material>
        </visual>
        <collision>
            <geometry>
                <cylinder length="0.008" radius="0.046"/>
            </geometry>
            <origin rpy="0 0 0" xyz="0 0 0"/>
        </collision>
        <inertial>
            <mass value="5"/>
            <inertia ixx="0.2" ixy="0.0" ixz="0.0" iyy="0.2" iyz="0.0" izz="0.1"/>
        </inertial>
    </link>
  
    <joint name="base_to_rwheel" type="continuous">
        <parent link="base_link"/>
        <child link="rwheel"/>
        <origin xyz="0 -0.115 0.046" rpy="-1.5708 0 0"/>
    </joint>
  
    <link name="fwheel_attach">
        <visual>
            <geometry>
                <cylinder length="0.060" radius="0.023"/>
            </geometry>
            <origin rpy="0 0 0" xyz="0.13 0 0.08"/>
            <material name="white">
                <color rgba="1 1 1 1"/>
            </material>
        </visual>
        <collision>
            <geometry>
                <cylinder length="0.060" radius="0.023"/>
            </geometry>
            <origin rpy="0 0 0" xyz="0.13 0 0.08"/>
        </collision>
    </link>
  
    <joint name="base_to_fattach" type="fixed">
        <parent link="base_link"/>
        <child link="fwheel_attach"/>
        <origin xyz="0 0 0" rpy="0 0 0"/>
    </joint>
  
    <link name="fwheel">
        <visual>
            <geometry>
                <cylinder length="0.005" radius="0.020"/>
            </geometry>
            <origin rpy="1.578 0 0" xyz="0 0 0"/>
            <material name="black">
                <color rgba="0 0 0 1"/>
            </material>
        </visual>
        <collision>
            <geometry>
                <cylinder length="0.005" radius="0.020"/>
            </geometry>
            <origin rpy="1.578 0 0" xyz="0 0 0"/>
        </collision>
    </link>
  
    <joint name="base_to_fwheel" type="fixed">
        <parent link="base_link"/>
        <child link="fwheel"/>
        <origin xyz="0.13 0 0.02" rpy="0 0 0"/>
    </joint>
  
    <link name="scanner">
        <visual>
            <geometry>
            <box size="0.015 0.045 0.015"/>
            </geometry>
            <origin rpy="0 0 0" xyz="0.022 0 0.015"/>
            <material name="black">
            <color rgba="0 0 0 1"/>
            </material>
        </visual>
    </link>
  
    <joint name="base_to_scanner" type="fixed">
        <parent link="base_link"/>
        <child link="scanner"/>
        <origin xyz="0.105 0 0.22" rpy="0 0 0"/>
    </joint>
</robot>