<?xml version="1.0" ?>
<!-- =================================================================================== -->
<!-- |    This document was autogenerated by xacro from urdf/fobo2.xacro               | -->
<!-- |    EDITING THIS FILE BY HAND IS NOT RECOMMENDED                                 | -->
<!-- =================================================================================== -->
<robot xmlns:xacro="http://www.ros.org/wiki/xacro" name="fobo2">
  <!-- Define parameters of chassis -->
  <!-- Motor cylinder parameters -->
  <!-- wheel parameters -->
  <!-- Ball parameters -->
  <!-- Stick length can't be automatically calculated -->
  <!-- define colors -->
  <material name="white">
    <color rgba="1 1 1 1"/>
  </material>
  <material name="black">
    <color rgba="0 0 0 1"/>
  </material>
  <material name="red">
    <color rgba="1 0 0 1"/>
  </material>
  <!-- link macros -->
  <!-- Define links joints macros  -->
  <!-- Base link -->
  <link name="base_link">
    <visual>
      <geometry>
        <box size="0.55 0.35 0.1"/>
      </geometry>
      <origin rpy="0 0 0" xyz="0 0 0"/>
      <material name="white">
        <!-- <color rgba="1 1 1 1"/> -->
      </material>
    </visual>
    <collision>
      <geometry>
        <box size="0.55 0.35 0.1"/>
      </geometry>
      <origin rpy="0 0 0" xyz="0 0 0"/>
    </collision>
    <inertial>
      <mass value="1"/>
      <inertia ixx="0.011041666666666665" ixy="0" ixz="0" iyy="0.02604166666666667" iyz="0" izz="0.02604166666666667"/>
    </inertial>
  </link>
  <!-- Motor links -->
  <link name="motor-right">
    <visual>
      <geometry>
        <cylinder radius="0.01" length="0.3"/>
      </geometry>
      <origin rpy="0 0 0" xyz="0 0 0"/>
      <material name="white">
        <color rgba="1 1 1 1"/>
      </material>
    </visual>
    <collision>
      <geometry>
        <cylinder radius="0.01" length="0.3"/>
      </geometry>
      <origin rpy="0 0 0" xyz="0 0 0"/>
    </collision>
    <inertial>
      <mass value="1"/>
      <inertia ixx="0.007525" ixy="0" ixz="0" iyy="0.007525" iyz="0" izz="5e-05"/>
    </inertial>
  </link>
  <link name="motor-left">
    <visual>
      <geometry>
        <cylinder radius="0.01" length="0.3"/>
      </geometry>
      <origin rpy="0 0 0" xyz="0 0 0"/>
      <material name="white">
        <color rgba="1 1 1 1"/>
      </material>
    </visual>
    <collision>
      <geometry>
        <cylinder radius="0.01" length="0.3"/>
      </geometry>
      <origin rpy="0 0 0" xyz="0 0 0"/>
    </collision>
    <inertial>
      <mass value="1"/>
      <inertia ixx="0.007525" ixy="0" ixz="0" iyy="0.007525" iyz="0" izz="5e-05"/>
    </inertial>
  </link>
  <!-- Wheel links -->
  <link name="wheel-right">
    <visual>
      <geometry>
        <cylinder radius="0.225" length="0.1"/>
      </geometry>
      <origin rpy="0 0 0" xyz="0 0 0"/>
      <material name="black">
        <color rgba="1 1 1 1"/>
      </material>
    </visual>
    <collision>
      <geometry>
        <cylinder radius="0.225" length="0.1"/>
      </geometry>
      <origin rpy="0 0 0" xyz="0 0 0"/>
    </collision>
    <inertial>
      <mass value="1"/>
      <inertia ixx="0.013489583333333334" ixy="0" ixz="0" iyy="0.013489583333333334" iyz="0" izz="0.0253125"/>
    </inertial>
  </link>
  <link name="wheel-left">
    <visual>
      <geometry>
        <cylinder radius="0.225" length="0.1"/>
      </geometry>
      <origin rpy="0 0 0" xyz="0 0 0"/>
      <material name="black">
        <color rgba="1 1 1 1"/>
      </material>
    </visual>
    <collision>
      <geometry>
        <cylinder radius="0.225" length="0.1"/>
      </geometry>
      <origin rpy="0 0 0" xyz="0 0 0"/>
    </collision>
    <inertial>
      <mass value="1"/>
      <inertia ixx="0.013489583333333334" ixy="0" ixz="0" iyy="0.013489583333333334" iyz="0" izz="0.0253125"/>
    </inertial>
  </link>
  <!-- Ball links -->
  <link name="stick-front">
    <visual>
      <geometry>
        <cylinder radius="0.015" length="0.2655"/>
      </geometry>
      <origin rpy="0 0 0" xyz="0 0 0"/>
      <material name="black">
        <color rgba="1 1 1 1"/>
      </material>
    </visual>
    <collision>
      <geometry>
        <cylinder radius="0.015" length="0.2655"/>
      </geometry>
      <origin rpy="0 0 0" xyz="0 0 0"/>
    </collision>
    <inertial>
      <mass value="0.015"/>
      <inertia ixx="8.89565625e-05" ixy="0" ixz="0" iyy="8.89565625e-05" iyz="0" izz="1.6875e-06"/>
    </inertial>
  </link>
  <link name="stick-back">
    <visual>
      <geometry>
        <cylinder radius="0.015" length="0.2655"/>
      </geometry>
      <origin rpy="0 0 0" xyz="0 0 0"/>
      <material name="black">
        <color rgba="1 1 1 1"/>
      </material>
    </visual>
    <collision>
      <geometry>
        <cylinder radius="0.015" length="0.2655"/>
      </geometry>
      <origin rpy="0 0 0" xyz="0 0 0"/>
    </collision>
    <inertial>
      <mass value="0.015"/>
      <inertia ixx="8.89565625e-05" ixy="0" ixz="0" iyy="8.89565625e-05" iyz="0" izz="1.6875e-06"/>
    </inertial>
  </link>
  <link name="ball-front">
    <visual>
      <geometry>
        <sphere radius="0.015"/>
      </geometry>
      <origin rpy="0 0 0" xyz="0 0 0"/>
      <material name="red">
        <color rgba="1 1 1 1"/>
      </material>
    </visual>
    <collision>
      <geometry>
        <sphere radius="0.015"/>
      </geometry>
      <origin rpy="0 0 0" xyz="0 0 0"/>
    </collision>
    <inertial>
      <mass value="1"/>
      <inertia ixx="8.999999999999999e-05" ixy="0" ixz="0" iyy="8.999999999999999e-05" iyz="0" izz="8.999999999999999e-05"/>
    </inertial>
  </link>
  <link name="ball-back">
    <visual>
      <geometry>
        <sphere radius="0.015"/>
      </geometry>
      <origin rpy="0 0 0" xyz="0 0 0"/>
      <material name="red">
        <color rgba="1 1 1 1"/>
      </material>
    </visual>
    <collision>
      <geometry>
        <sphere radius="0.015"/>
      </geometry>
      <origin rpy="0 0 0" xyz="0 0 0"/>
    </collision>
    <inertial>
      <mass value="1"/>
      <inertia ixx="8.999999999999999e-05" ixy="0" ixz="0" iyy="8.999999999999999e-05" iyz="0" izz="8.999999999999999e-05"/>
    </inertial>
  </link>
  <!-- Motor joints -->
  <joint name="motor-right-base" type="fixed">
    <parent link="base_link"/>
    <child link="motor-right"/>
    <origin xyz="0 0.034999999999999996 -0.055" rpy="0 1.5707 1.5707"/>
  </joint>
  <joint name="motor-left-base" type="fixed">
    <parent link="base_link"/>
    <child link="motor-left"/>
    <origin xyz="0 -0.034999999999999996 -0.055" rpy="0 1.5707 1.5707"/>
  </joint>
  <!-- Wheel joints -->
  <joint name="wheel-motor-right" type="continuous">
    <parent link="motor-right"/>
    <child link="wheel-right"/>
    <origin xyz="0 0 0.2" rpy="0 0 0"/>
    <axis xyz="0 0 1"/>
  </joint>
  <joint name="wheel-motor-left" type="continuous">
    <parent link="motor-left"/>
    <child link="wheel-left"/>
    <origin xyz="0 0 -0.2" rpy="0 0 0"/>
    <axis xyz="0 0 1"/>
  </joint>
  <!-- Ball joints -->
  <joint name="stick-front-base" type="fixed">
    <parent link="base_link"/>
    <child link="stick-front"/>
    <origin xyz="0.22500000000000003 0 -0.13275" rpy="0 0 0"/>
  </joint>
  <joint name="stick-back-base" type="fixed">
    <parent link="base_link"/>
    <child link="stick-back"/>
    <origin xyz="-0.22500000000000003 0 -0.13275" rpy="0 0 0"/>
  </joint>
  <joint name="ball-front-joint" type="floating">
    <parent link="stick-front"/>
    <child link="ball-front"/>
    <origin xyz="0 0 -0.13275" rpy="0 0 0"/>
    <!-- <axis xyz="0 0 1"/>  -->
  </joint>
  <joint name="ball-back-joint" type="floating">
    <parent link="stick-back"/>
    <child link="ball-back"/>
    <origin xyz="0 0 -0.13275" rpy="0 0 0"/>
    <!-- <axis xyz="0 0 1"/>  -->
  </joint>
</robot>
