<?xml version="1.0" ?>
<!-- =================================================================================== -->
<!-- |    This document was autogenerated by xacro from urdf/fobo2.xacro               | -->
<!-- |    EDITING THIS FILE BY HAND IS NOT RECOMMENDED                                 | -->
<!-- =================================================================================== -->
<robot xmlns:xacro="http://www.ros.org/wiki/xacro" name="fobo2">
  <!-- Define parameters of chassis -->
  <!-- Motor cylinder parameters -->
  <!-- wheel parameters -->
  <!-- Ball parameters -->
  <!-- Stick length can't be automatically calculated -->
  <!-- define colors -->
  <material name="white">
    <color rgba="1 1 1 1"/>
  </material>
  <material name="black">
    <color rgba="0 0 0 1"/>
  </material>
  <material name="red">
    <color rgba="1 0 0 1"/>
  </material>
  <!-- link macros -->
  <!-- Define links joints macros  -->
  <!-- Base link -->
  <link name="base_link">
    <visual>
      <geometry>
        <box size="0.55 0.35 0.01"/>
      </geometry>
      <origin rpy="0 0 0" xyz="0 0 0"/>
      <material name="white">
        <!-- <color rgba="1 1 1 1"/> -->
      </material>
    </visual>
    <collision>
      <geometry>
        <box size="0.55 0.35 0.01"/>
      </geometry>
      <origin rpy="0 0 0" xyz="0 0 0"/>
    </collision>
    <inertial>
      <mass value="1"/>
      <inertia ixx="0.010216666666666666" ixy="0" ixz="0" iyy="0.02521666666666667" iyz="0" izz="0.02521666666666667"/>
    </inertial>
  </link>
  <!-- Motor links -->
  <link name="motor-right">
    <visual>
      <geometry>
        <cylinder radius="0.032" length="0.105"/>
      </geometry>
      <origin rpy="0 0 0" xyz="0 0 0"/>
      <material name="white">
        <color rgba="1 1 1 1"/>
      </material>
    </visual>
    <collision>
      <geometry>
        <cylinder radius="0.032" length="0.105"/>
      </geometry>
      <origin rpy="0 0 0" xyz="0 0 0"/>
    </collision>
    <inertial>
      <mass value="0.438"/>
      <inertia ixx="0.0005145404999999999" ixy="0" ixz="0" iyy="0.0005145404999999999" iyz="0" izz="0.00022425600000000002"/>
    </inertial>
  </link>
  <link name="motor-left">
    <visual>
      <geometry>
        <cylinder radius="0.032" length="0.105"/>
      </geometry>
      <origin rpy="0 0 0" xyz="0 0 0"/>
      <material name="white">
        <color rgba="1 1 1 1"/>
      </material>
    </visual>
    <collision>
      <geometry>
        <cylinder radius="0.032" length="0.105"/>
      </geometry>
      <origin rpy="0 0 0" xyz="0 0 0"/>
    </collision>
    <inertial>
      <mass value="0.438"/>
      <inertia ixx="0.0005145404999999999" ixy="0" ixz="0" iyy="0.0005145404999999999" iyz="0" izz="0.00022425600000000002"/>
    </inertial>
  </link>
  <!-- Wheel links -->
  <link name="wheel-right">
    <visual>
      <geometry>
        <cylinder radius="0.12" length="0.088"/>
      </geometry>
      <origin rpy="0 0 0" xyz="0 0 0"/>
      <material name="black">
        <color rgba="1 1 1 1"/>
      </material>
    </visual>
    <collision>
      <geometry>
        <cylinder radius="0.12" length="0.088"/>
      </geometry>
      <origin rpy="0 0 0" xyz="0 0 0"/>
    </collision>
    <inertial>
      <mass value="0.237"/>
      <inertia ixx="0.0010061439999999998" ixy="0" ixz="0" iyy="0.0010061439999999998" iyz="0" izz="0.0017063999999999996"/>
    </inertial>
  </link>
  <link name="wheel-left">
    <visual>
      <geometry>
        <cylinder radius="0.12" length="0.088"/>
      </geometry>
      <origin rpy="0 0 0" xyz="0 0 0"/>
      <material name="black">
        <color rgba="1 1 1 1"/>
      </material>
    </visual>
    <collision>
      <geometry>
        <cylinder radius="0.12" length="0.088"/>
      </geometry>
      <origin rpy="0 0 0" xyz="0 0 0"/>
    </collision>
    <inertial>
      <mass value="0.237"/>
      <inertia ixx="0.0010061439999999998" ixy="0" ixz="0" iyy="0.0010061439999999998" iyz="0" izz="0.0017063999999999996"/>
    </inertial>
  </link>
  <!-- Ball links -->
  <link name="stick-front">
    <visual>
      <geometry>
        <cylinder radius="0.015" length="0.102"/>
      </geometry>
      <origin rpy="0 0 0" xyz="0 0 0"/>
      <material name="black">
        <color rgba="1 1 1 1"/>
      </material>
    </visual>
    <collision>
      <geometry>
        <cylinder radius="0.015" length="0.102"/>
      </geometry>
      <origin rpy="0 0 0" xyz="0 0 0"/>
    </collision>
    <inertial>
      <mass value="0.015"/>
      <inertia ixx="1.3848749999999998e-05" ixy="0" ixz="0" iyy="1.3848749999999998e-05" iyz="0" izz="1.6875e-06"/>
    </inertial>
  </link>
  <link name="stick-back">
    <visual>
      <geometry>
        <cylinder radius="0.015" length="0.102"/>
      </geometry>
      <origin rpy="0 0 0" xyz="0 0 0"/>
      <material name="black">
        <color rgba="1 1 1 1"/>
      </material>
    </visual>
    <collision>
      <geometry>
        <cylinder radius="0.015" length="0.102"/>
      </geometry>
      <origin rpy="0 0 0" xyz="0 0 0"/>
    </collision>
    <inertial>
      <mass value="0.015"/>
      <inertia ixx="1.3848749999999998e-05" ixy="0" ixz="0" iyy="1.3848749999999998e-05" iyz="0" izz="1.6875e-06"/>
    </inertial>
  </link>
  <link name="ball-front">
    <visual>
      <geometry>
        <sphere radius="0.03"/>
      </geometry>
      <origin rpy="0 0 0" xyz="0 0 0"/>
      <material name="red">
        <color rgba="1 1 1 1"/>
      </material>
    </visual>
    <collision>
      <geometry>
        <sphere radius="0.03"/>
      </geometry>
      <origin rpy="0 0 0" xyz="0 0 0"/>
    </collision>
    <inertial>
      <mass value="1"/>
      <inertia ixx="0.00035999999999999997" ixy="0" ixz="0" iyy="0.00035999999999999997" iyz="0" izz="0.00035999999999999997"/>
    </inertial>
  </link>
  <link name="ball-back">
    <visual>
      <geometry>
        <sphere radius="0.03"/>
      </geometry>
      <origin rpy="0 0 0" xyz="0 0 0"/>
      <material name="red">
        <color rgba="1 1 1 1"/>
      </material>
    </visual>
    <collision>
      <geometry>
        <sphere radius="0.03"/>
      </geometry>
      <origin rpy="0 0 0" xyz="0 0 0"/>
    </collision>
    <inertial>
      <mass value="1"/>
      <inertia ixx="0.00035999999999999997" ixy="0" ixz="0" iyy="0.00035999999999999997" iyz="0" izz="0.00035999999999999997"/>
    </inertial>
  </link>
  <!-- Motor joints -->
  <joint name="motor-right-base" type="fixed">
    <parent link="base_link"/>
    <child link="motor-right"/>
    <origin xyz="0 0.1325 -0.026000000000000002" rpy="0 1.5707 1.5707"/>
  </joint>
  <joint name="motor-left-base" type="fixed">
    <parent link="base_link"/>
    <child link="motor-left"/>
    <origin xyz="0 -0.1325 -0.026000000000000002" rpy="0 1.5707 1.5707"/>
  </joint>
  <!-- Wheel joints -->
  <joint name="wheel-motor-right" type="continuous">
    <parent link="motor-right"/>
    <child link="wheel-right"/>
    <origin xyz="0 0 0.0965" rpy="0 0 0"/>
    <axis xyz="0 0 1"/>
  </joint>
  <joint name="wheel-motor-left" type="continuous">
    <parent link="motor-left"/>
    <child link="wheel-left"/>
    <origin xyz="0 0 -0.0965" rpy="0 0 0"/>
    <axis xyz="0 0 1"/>
  </joint>
  <!-- Ball joints -->
  <joint name="stick-front-base" type="fixed">
    <parent link="base_link"/>
    <child link="stick-front"/>
    <origin xyz="0.22500000000000003 0 -0.051" rpy="0 0 0"/>
  </joint>
  <joint name="stick-back-base" type="fixed">
    <parent link="base_link"/>
    <child link="stick-back"/>
    <origin xyz="-0.22500000000000003 0 -0.051" rpy="0 0 0"/>
  </joint>
  <joint name="ball-front-joint" type="floating">
    <parent link="base_link"/>
    <child link="ball-front"/>
    <origin xyz="0.22500000000000003 0 -0.115" rpy="0 0 0"/>
    <!-- <axis xyz="0 0 1"/>  -->
  </joint>
  <joint name="ball-back-joint" type="floating">
    <parent link="base_link"/>
    <child link="ball-back"/>
    <origin xyz="-0.22500000000000003 0 -0.115" rpy="0 0 0"/>
    <!-- <axis xyz="0 0 1"/>  -->
  </joint>
</robot>
